Traceback (most recent call last):
  File "/opt/anaconda3/envs/aciar/lib/python3.11/site-packages/jupyter_cache/executors/utils.py", line 58, in single_nb_execution
    executenb(
  File "/opt/anaconda3/envs/aciar/lib/python3.11/site-packages/nbclient/client.py", line 1314, in execute
    return NotebookClient(nb=nb, resources=resources, km=km, **kwargs).execute()
           ^^^^^^^^^^^^^^^^^^^^^^^^^^^^^^^^^^^^^^^^^^^^^^^^^^^^^^^^^^^^^^^^^^^^^
  File "/opt/anaconda3/envs/aciar/lib/python3.11/site-packages/jupyter_core/utils/__init__.py", line 173, in wrapped
    return loop.run_until_complete(inner)
           ^^^^^^^^^^^^^^^^^^^^^^^^^^^^^^
  File "/opt/anaconda3/envs/aciar/lib/python3.11/asyncio/base_events.py", line 653, in run_until_complete
    return future.result()
           ^^^^^^^^^^^^^^^
  File "/opt/anaconda3/envs/aciar/lib/python3.11/site-packages/nbclient/client.py", line 709, in async_execute
    await self.async_execute_cell(
  File "/opt/anaconda3/envs/aciar/lib/python3.11/site-packages/nbclient/client.py", line 1062, in async_execute_cell
    await self._check_raise_for_error(cell, cell_index, exec_reply)
  File "/opt/anaconda3/envs/aciar/lib/python3.11/site-packages/nbclient/client.py", line 918, in _check_raise_for_error
    raise CellExecutionError.from_cell_and_msg(cell, exec_reply_content)
nbclient.exceptions.CellExecutionError: An error occurred while executing the following cell:
------------------
ds = xr.open_dataarray('wc2.1_10m_elev.tif')
ds = ds.sel(band=1)
ele_plot = ds.hvplot(x='x',y='y',width=1000,height=500);

dfp = pd.read_csv('occ.csv',index_col=0)
loc_plot = dfp.hvplot.scatter(x='lon',y='lat');

dfp*loc_plot
------------------


[0;31m---------------------------------------------------------------------------[0m
[0;31mAttributeError[0m                            Traceback (most recent call last)
[0;32m/tmp/ipykernel_1535887/799788783.py[0m in [0;36m?[0;34m()[0m
[1;32m      2[0m [0mds[0m [0;34m=[0m [0mds[0m[0;34m.[0m[0msel[0m[0;34m([0m[0mband[0m[0;34m=[0m[0;36m1[0m[0;34m)[0m[0;34m[0m[0;34m[0m[0m
[1;32m      3[0m [0mele_plot[0m [0;34m=[0m [0mds[0m[0;34m.[0m[0mhvplot[0m[0;34m([0m[0mx[0m[0;34m=[0m[0;34m'x'[0m[0;34m,[0m[0my[0m[0;34m=[0m[0;34m'y'[0m[0;34m,[0m[0mwidth[0m[0;34m=[0m[0;36m1000[0m[0;34m,[0m[0mheight[0m[0;34m=[0m[0;36m500[0m[0;34m)[0m[0;34m;[0m[0;34m[0m[0;34m[0m[0m
[1;32m      4[0m [0;34m[0m[0m
[1;32m      5[0m [0mdfp[0m [0;34m=[0m [0mpd[0m[0;34m.[0m[0mread_csv[0m[0;34m([0m[0;34m'occ.csv'[0m[0;34m,[0m[0mindex_col[0m[0;34m=[0m[0;36m0[0m[0;34m)[0m[0;34m[0m[0;34m[0m[0m
[0;32m----> 6[0;31m [0mloc_plot[0m [0;34m=[0m [0mdfp[0m[0;34m.[0m[0mhvplot[0m[0;34m.[0m[0mscatter[0m[0;34m([0m[0mx[0m[0;34m=[0m[0;34m'lon'[0m[0;34m,[0m[0my[0m[0;34m=[0m[0;34m'lat'[0m[0;34m)[0m[0;34m;[0m[0;34m[0m[0;34m[0m[0m
[0m[1;32m      7[0m [0;34m[0m[0m
[1;32m      8[0m [0mdfp[0m[0;34m*[0m[0mloc_plot[0m[0;34m[0m[0;34m[0m[0m

[0;32m/opt/anaconda3/envs/aciar/lib/python3.11/site-packages/pandas/core/generic.py[0m in [0;36m?[0;34m(self, name)[0m
[1;32m   5898[0m             [0;32mand[0m [0mname[0m [0;32mnot[0m [0;32min[0m [0mself[0m[0;34m.[0m[0m_accessors[0m[0;34m[0m[0;34m[0m[0m
[1;32m   5899[0m             [0;32mand[0m [0mself[0m[0;34m.[0m[0m_info_axis[0m[0;34m.[0m[0m_can_hold_identifiers_and_holds_name[0m[0;34m([0m[0mname[0m[0;34m)[0m[0;34m[0m[0;34m[0m[0m
[1;32m   5900[0m         ):
[1;32m   5901[0m             [0;32mreturn[0m [0mself[0m[0;34m[[0m[0mname[0m[0;34m][0m[0;34m[0m[0;34m[0m[0m
[0;32m-> 5902[0;31m         [0;32mreturn[0m [0mobject[0m[0;34m.[0m[0m__getattribute__[0m[0;34m([0m[0mself[0m[0;34m,[0m [0mname[0m[0;34m)[0m[0;34m[0m[0;34m[0m[0m
[0m
[0;31mAttributeError[0m: 'DataFrame' object has no attribute 'hvplot'

