Traceback (most recent call last):
  File "/opt/anaconda3/envs/aciar/lib/python3.11/site-packages/jupyter_cache/executors/utils.py", line 58, in single_nb_execution
    executenb(
  File "/opt/anaconda3/envs/aciar/lib/python3.11/site-packages/nbclient/client.py", line 1314, in execute
    return NotebookClient(nb=nb, resources=resources, km=km, **kwargs).execute()
           ^^^^^^^^^^^^^^^^^^^^^^^^^^^^^^^^^^^^^^^^^^^^^^^^^^^^^^^^^^^^^^^^^^^^^
  File "/opt/anaconda3/envs/aciar/lib/python3.11/site-packages/jupyter_core/utils/__init__.py", line 173, in wrapped
    return loop.run_until_complete(inner)
           ^^^^^^^^^^^^^^^^^^^^^^^^^^^^^^
  File "/opt/anaconda3/envs/aciar/lib/python3.11/asyncio/base_events.py", line 653, in run_until_complete
    return future.result()
           ^^^^^^^^^^^^^^^
  File "/opt/anaconda3/envs/aciar/lib/python3.11/site-packages/nbclient/client.py", line 709, in async_execute
    await self.async_execute_cell(
  File "/opt/anaconda3/envs/aciar/lib/python3.11/site-packages/nbclient/client.py", line 1062, in async_execute_cell
    await self._check_raise_for_error(cell, cell_index, exec_reply)
  File "/opt/anaconda3/envs/aciar/lib/python3.11/site-packages/nbclient/client.py", line 918, in _check_raise_for_error
    raise CellExecutionError.from_cell_and_msg(cell, exec_reply_content)
nbclient.exceptions.CellExecutionError: An error occurred while executing the following cell:
------------------
ds = xr.open_dataarray('wc2.1_10m_elev.tif')
ds = ds.sel(band=1)
ds.hvplot(x='x',y='y',width=1000,height=500)

dfp = pd.read_csv('occ.csv',index_col=0) *\
dfp.plot.scatter(x='lon',y='lat')


------------------


[0;31m---------------------------------------------------------------------------[0m
[0;31mNameError[0m                                 Traceback (most recent call last)
Cell [0;32mIn[3], line 6[0m
[1;32m      2[0m ds [38;5;241m=[39m ds[38;5;241m.[39msel(band[38;5;241m=[39m[38;5;241m1[39m)
[1;32m      3[0m ds[38;5;241m.[39mhvplot(x[38;5;241m=[39m[38;5;124m'[39m[38;5;124mx[39m[38;5;124m'[39m,y[38;5;241m=[39m[38;5;124m'[39m[38;5;124my[39m[38;5;124m'[39m,width[38;5;241m=[39m[38;5;241m1000[39m,height[38;5;241m=[39m[38;5;241m500[39m)
[1;32m      5[0m dfp [38;5;241m=[39m pd[38;5;241m.[39mread_csv([38;5;124m'[39m[38;5;124mocc.csv[39m[38;5;124m'[39m,index_col[38;5;241m=[39m[38;5;241m0[39m) [38;5;241m*[39m\
[0;32m----> 6[0m [43mdfp[49m[38;5;241m.[39mplot[38;5;241m.[39mscatter(x[38;5;241m=[39m[38;5;124m'[39m[38;5;124mlon[39m[38;5;124m'[39m,y[38;5;241m=[39m[38;5;124m'[39m[38;5;124mlat[39m[38;5;124m'[39m)

[0;31mNameError[0m: name 'dfp' is not defined

